Workbook

Sheet CONTROL DE LLAMADAS
A1: Nombre de Encuestador: | C1: JUAN FELIPE RAMIREZ LARRIVA | H1: P1 – Motivo principal | I1: P2 – Calificación | J1: Lógica condicional (IMPORTANTE) | L1: P3 – Competencia | N1: P4 – Reactivación | O1: P5 – Disposición Final
H2: Pregunta: | I2: Pregunta: | J2: Si responde: | L2: Pregunta: | M2: Si responde “Sí” → activar pregunta: | N2: Pregunta:
A3: Fila | B3: Fecha de llamada | C3: Estatus de CONTACT | D3: Plaza | E3: Numero Dv | F3: Nombre Dv | G3: fhUltimoCanje | H3: “En una palabra o frase corta, ¿cuál es la principal razón por la que hoy no estás colocando?” | I3: “Del 1 al 5 donde 5 es muy buena y 1 es mala, ¿cómo calificas tu experiencia con la sucursal?” | J3: 1, 2 o 3 → ir a sección “Área de Mejora” como podriamos mejorar? | K3: 4 o 5 → ir a sección “Fortaleza” | L3: “¿Actualmente trabajas con otra financiera?” | M3: “¿Qué es lo que más te gusta de trabajar con ellos?” | N3: ¿Qué Necesitas para ser exclusiva de CRECE CON VALES? | O3: “Si logramos resolver el punto que nos comentas, ¿te gustaría que te contactemos para revisar tu posible reactivación?”
J4: “¿Qué podríamos mejorar?” | K4: “¿Qué es lo que más valoras del servicio?” | O4: Si | P4: Tal vez | Q4: No
A5: 1 | B5: 46073 | C5: No contestó | D5: {=INDEX(BASE!$C:$C,MATCH($A5,BASE!$A:$A,0))} -> ACAYUCAN | E5: {=INDEX(BASE!E:E,MATCH($A5,BASE!$A:$A,0))} -> 86079 | F5: {=INDEX(BASE!F:F,MATCH($A5,BASE!$A:$A,0))} -> MARIA DE LOS ANGELES MEZA REYES | G5: {=INDEX(BASE!J:J,MATCH($A5,BASE!$A:$A,0))} -> 46052
A6: 2 | B6: 46073 | C6: No contestó | D6: {=INDEX(BASE!$C:$C,MATCH($A6,BASE!$A:$A,0))} -> ACAYUCAN | E6: {=INDEX(BASE!E:E,MATCH($A6,BASE!$A:$A,0))} -> 86166 | F6: {=INDEX(BASE!F:F,MATCH($A6,BASE!$A:$A,0))} -> GABRIELA SANCHEZ GONZALEZ | G6: {=INDEX(BASE!J:J,MATCH($A6,BASE!$A:$A,0))} -> 46051
A7: 3 | B7: 46073 | C7: No contestó | D7: {=INDEX(BASE!$C:$C,MATCH($A7,BASE!$A:$A,0))} -> ACAYUCAN | E7: {=INDEX(BASE!E:E,MATCH($A7,BASE!$A:$A,0))} -> 86052 | F7: {=INDEX(BASE!F:F,MATCH($A7,BASE!$A:$A,0))} -> MARIA DEL CARMEN CRUZ JIMENEZ | G7: {=INDEX(BASE!J:J,MATCH($A7,BASE!$A:$A,0))} -> 46014
A8: 4 | B8: 46073 | C8: No contestó | D8: {=INDEX(BASE!$C:$C,MATCH($A8,BASE!$A:$A,0))} -> ACAYUCAN | E8: {=INDEX(BASE!E:E,MATCH($A8,BASE!$A:$A,0))} -> 109938 | F8: {=INDEX(BASE!F:F,MATCH($A8,BASE!$A:$A,0))} -> PEREZ HERNANDEZ , PETRONILA | G8: {=INDEX(BASE!J:J,MATCH($A8,BASE!$A:$A,0))} -> 46050
A9: 5 | B9: 46073 | C9: Llamada efectiva (contestó) | D9: {=INDEX(BASE!$C:$C,MATCH($A9,BASE!$A:$A,0))} -> ACAYUCAN | E9: {=INDEX(BASE!E:E,MATCH($A9,BASE!$A:$A,0))} -> 86237 | F9: {=INDEX(BASE!F:F,MATCH($A9,BASE!$A:$A,0))} -> HERLINDA LOPEZ NO | G9: {=INDEX(BASE!J:J,MATCH($A9,BASE!$A:$A,0))} -> 46054 | H9: falta de apoyo del promotor, no se le da seguimiento | I9: 5 | K9: facilidades en el servicio de pagos | L9: NO
A10: 6 | B10: 46073 | C10: Reagendar llamada | D10: {=INDEX(BASE!$C:$C,MATCH($A10,BASE!$A:$A,0))} -> ACAYUCAN | E10: {=INDEX(BASE!E:E,MATCH($A10,BASE!$A:$A,0))} -> 116240 | F10: {=INDEX(BASE!F:F,MATCH($A10,BASE!$A:$A,0))} -> NOLASCO BLANCO , ERICK NAHIM | G10: {=INDEX(BASE!J:J,MATCH($A10,BASE!$A:$A,0))} -> 46050
A11: 7 | B11: 46073 | C11: Buzón | D11: {=INDEX(BASE!$C:$C,MATCH($A11,BASE!$A:$A,0))} -> ACAYUCAN | E11: {=INDEX(BASE!E:E,MATCH($A11,BASE!$A:$A,0))} -> 116013 | F11: {=INDEX(BASE!F:F,MATCH($A11,BASE!$A:$A,0))} -> HERNANDEZ MODESTO , ANA BEATRIZ | G11: {=INDEX(BASE!J:J,MATCH($A11,BASE!$A:$A,0))} -> 46028
A12: 8 | B12: 46073 | C12: No contestó | D12: {=INDEX(BASE!$C:$C,MATCH($A12,BASE!$A:$A,0))} -> ACAYUCAN | E12: {=INDEX(BASE!E:E,MATCH($A12,BASE!$A:$A,0))} -> 86024 | F12: {=INDEX(BASE!F:F,MATCH($A12,BASE!$A:$A,0))} -> MARTHA REINA REYES GABINO | G12: {=INDEX(BASE!J:J,MATCH($A12,BASE!$A:$A,0))} -> 45994
A13: 9 | B13: 46073 | C13: No contestó | D13: {=INDEX(BASE!$C:$C,MATCH($A13,BASE!$A:$A,0))} -> ACAYUCAN | E13: {=INDEX(BASE!E:E,MATCH($A13,BASE!$A:$A,0))} -> 86065 | F13: {=INDEX(BASE!F:F,MATCH($A13,BASE!$A:$A,0))} -> NATALI DE MONSERRAT RUIZ VERGARA | G13: {=INDEX(BASE!J:J,MATCH($A13,BASE!$A:$A,0))} -> 45994
A14: 10 | B14: 46073 | C14: Se negó a contestar | D14: {=INDEX(BASE!$C:$C,MATCH($A14,BASE!$A:$A,0))} -> ACAYUCAN | E14: {=INDEX(BASE!E:E,MATCH($A14,BASE!$A:$A,0))} -> 86072 | F14: {=INDEX(BASE!F:F,MATCH($A14,BASE!$A:$A,0))} -> ELIZABETH GUILLEN FERNANDEZ | G14: {=INDEX(BASE!J:J,MATCH($A14,BASE!$A:$A,0))} -> 45962
A15: 11 | B15: 46073 | C15: Se negó a contestar | D15: {=INDEX(BASE!$C:$C,MATCH($A15,BASE!$A:$A,0))} -> ACAYUCAN | E15: {=INDEX(BASE!E:E,MATCH($A15,BASE!$A:$A,0))} -> 86035 | F15: {=INDEX(BASE!F:F,MATCH($A15,BASE!$A:$A,0))} -> MARIA CRISTINA MUÑOZ CARDENAS | G15: {=INDEX(BASE!J:J,MATCH($A15,BASE!$A:$A,0))} -> 46054
A16: 12 | B16: 46073 | C16: No contestó | D16: {=INDEX(BASE!$C:$C,MATCH($A16,BASE!$A:$A,0))} -> ACAYUCAN | E16: {=INDEX(BASE!E:E,MATCH($A16,BASE!$A:$A,0))} -> 109931 | F16: {=INDEX(BASE!F:F,MATCH($A16,BASE!$A:$A,0))} -> AGUIRRE ENRIQUEZ , GUADALUPE | G16: {=INDEX(BASE!J:J,MATCH($A16,BASE!$A:$A,0))} -> 46024
A17: 13 | B17: 46073 | C17: No contestó | D17: {=INDEX(BASE!$C:$C,MATCH($A17,BASE!$A:$A,0))} -> ACAYUCAN | E17: {=INDEX(BASE!E:E,MATCH($A17,BASE!$A:$A,0))} -> 103239 | F17: {=INDEX(BASE!F:F,MATCH($A17,BASE!$A:$A,0))} -> TADEO ANTONIO EVA | G17: {=INDEX(BASE!J:J,MATCH($A17,BASE!$A:$A,0))} -> 46054
A18: 14 | B18: 46073 | C18: Llamada efectiva (contestó) | D18: {=INDEX(BASE!$C:$C,MATCH($A18,BASE!$A:$A,0))} -> ACAYUCAN | E18: {=INDEX(BASE!E:E,MATCH($A18,BASE!$A:$A,0))} -> 86105 | F18: {=INDEX(BASE!F:F,MATCH($A18,BASE!$A:$A,0))} -> ANGELICA TREJO PEREZ | G18: {=INDEX(BASE!J:J,MATCH($A18,BASE!$A:$A,0))} -> 46045 | H18: Comenta que no hay apoyo en cobranza | I18: 2 | J18: estar al tanto y apoyar | L18: SI | M18: Tienen mejor atencion y seguimiento | N18: apoyo | O18: 1
A19: 15 | B19: 46073 | C19: Buzón | D19: {=INDEX(BASE!$C:$C,MATCH($A19,BASE!$A:$A,0))} -> ACAYUCAN | E19: {=INDEX(BASE!E:E,MATCH($A19,BASE!$A:$A,0))} -> 86149 | F19: {=INDEX(BASE!F:F,MATCH($A19,BASE!$A:$A,0))} -> PETRA RAMIREZ USCANGA | G19: {=INDEX(BASE!J:J,MATCH($A19,BASE!$A:$A,0))} -> 46056
A20: 16 | B20: 46073 | C20: Llamada efectiva (contestó) | D20: {=INDEX(BASE!$C:$C,MATCH($A20,BASE!$A:$A,0))} -> ACAYUCAN | E20: {=INDEX(BASE!E:E,MATCH($A20,BASE!$A:$A,0))} -> 86041 | F20: {=INDEX(BASE!F:F,MATCH($A20,BASE!$A:$A,0))} -> ZORAIDA MENDOZA DE JESUS | G20: {=INDEX(BASE!J:J,MATCH($A20,BASE!$A:$A,0))} -> 46056 | H20: falta de confianza, no se quiere arriesgar a que los clientes no le paguen | I20: 2 | J20: no hay motivacion por parte del personal | L20: SI | M20: tienen mejor atencion | N20: piensa en salir de colaborar | O20: 1
A21: 17 | B21: 46073 | C21: No contestó | D21: {=INDEX(BASE!$C:$C,MATCH($A21,BASE!$A:$A,0))} -> ACAYUCAN | E21: {=INDEX(BASE!E:E,MATCH($A21,BASE!$A:$A,0))} -> 86053 | F21: {=INDEX(BASE!F:F,MATCH($A21,BASE!$A:$A,0))} -> NICOLASA HERNANDEZ MARTINEZ | G21: {=INDEX(BASE!J:J,MATCH($A21,BASE!$A:$A,0))} -> 45980
A22: 18 | B22: 46073 | C22: Llamada efectiva (contestó) | D22: {=INDEX(BASE!$C:$C,MATCH($A22,BASE!$A:$A,0))} -> ACAYUCAN | E22: {=INDEX(BASE!E:E,MATCH($A22,BASE!$A:$A,0))} -> 86037 | F22: {=INDEX(BASE!F:F,MATCH($A22,BASE!$A:$A,0))} -> ANA LUISA ZENTENO MARTINEZ | G22: {=INDEX(BASE!J:J,MATCH($A22,BASE!$A:$A,0))} -> 46003 | H22: le teme a que clientes no le paguen | I22: 5 | K22: la atencion y bonificacion | L22: SI | M22: las bonificaciones y el apoyo en cobranza | N22: paciencia | O22: 1
A23: 19 | B23: 46073 | C23: Buzón | D23: {=INDEX(BASE!$C:$C,MATCH($A23,BASE!$A:$A,0))} -> ACAYUCAN | E23: {=INDEX(BASE!E:E,MATCH($A23,BASE!$A:$A,0))} -> 116138 | F23: {=INDEX(BASE!F:F,MATCH($A23,BASE!$A:$A,0))} -> GUILLEN SANTIAGO , ALONDRA | G23: {=INDEX(BASE!J:J,MATCH($A23,BASE!$A:$A,0))} -> 45997
A24: 20 | B24: 46073 | C24: Se negó a contestar | D24: {=INDEX(BASE!$C:$C,MATCH($A24,BASE!$A:$A,0))} -> ACAYUCAN | E24: {=INDEX(BASE!E:E,MATCH($A24,BASE!$A:$A,0))} -> 86083 | F24: {=INDEX(BASE!F:F,MATCH($A24,BASE!$A:$A,0))} -> DORA PEREZ GOMEZ | G24: {=INDEX(BASE!J:J,MATCH($A24,BASE!$A:$A,0))} -> 46017 | H24: no ha buscado clientes | I24: 5 | K24: ya no siguio en la llamada
A25: 21 | B25: 46073 | C25: No contestó | D25: {=INDEX(BASE!$C:$C,MATCH($A25,BASE!$A:$A,0))} -> ACAYUCAN | E25: {=INDEX(BASE!E:E,MATCH($A25,BASE!$A:$A,0))} -> 103924 | F25: {=INDEX(BASE!F:F,MATCH($A25,BASE!$A:$A,0))} -> CORDERO RAMIREZ MARIBEL | G25: {=INDEX(BASE!J:J,MATCH($A25,BASE!$A:$A,0))} -> 45965
A26: 22 | B26: 46073 | C26: No contestó | D26: {=INDEX(BASE!$C:$C,MATCH($A26,BASE!$A:$A,0))} -> ACAYUCAN | E26: {=INDEX(BASE!E:E,MATCH($A26,BASE!$A:$A,0))} -> 107170 | F26: {=INDEX(BASE!F:F,MATCH($A26,BASE!$A:$A,0))} -> ISIDORO CANDIDO , ALEJANDRA | G26: {=INDEX(BASE!J:J,MATCH($A26,BASE!$A:$A,0))} -> 45962
A27: 23 | B27: 46073 | C27: Llamada efectiva (contestó) | D27: {=INDEX(BASE!$C:$C,MATCH($A27,BASE!$A:$A,0))} -> ACAYUCAN | E27: {=INDEX(BASE!E:E,MATCH($A27,BASE!$A:$A,0))} -> 110417 | F27: {=INDEX(BASE!F:F,MATCH($A27,BASE!$A:$A,0))} -> PULIDO LICONA , VERONICA | G27: {=INDEX(BASE!J:J,MATCH($A27,BASE!$A:$A,0))} -> 46003 | H27: vive en una zona donde hay muchos prestanombres | I27: 3 | J27: ayuda en cobranza, no hay apoyo | L27: SI | M27: apoyan con la cobranza | N27: mas atencion por parte de la financiera | Q27: 1
A28: 24 | B28: 46073 | C28: Llamada efectiva (contestó) | D28: {=INDEX(BASE!$C:$C,MATCH($A28,BASE!$A:$A,0))} -> ACAYUCAN | E28: {=INDEX(BASE!E:E,MATCH($A28,BASE!$A:$A,0))} -> 108567 | F28: {=INDEX(BASE!F:F,MATCH($A28,BASE!$A:$A,0))} -> DOMINGUEZ ALFONSO , MARIA ELENA | G28: {=INDEX(BASE!J:J,MATCH($A28,BASE!$A:$A,0))} -> 46054 | H28: no lleva prisa, no se quiere saturar | I28: 5 | K28: se le ha brindado apoyo | L28: SI | M28: se siente comoda | N28: tener una buena selección de clientes | O28: 1
A29: 25 | B29: 46073 | C29: No contestó | D29: {=INDEX(BASE!$C:$C,MATCH($A29,BASE!$A:$A,0))} -> ALTAMIRA | E29: {=INDEX(BASE!E:E,MATCH($A29,BASE!$A:$A,0))} -> 57216 | F29: {=INDEX(BASE!F:F,MATCH($A29,BASE!$A:$A,0))} -> MARIA GUADALUPE AQUINO BANDA | G29: {=INDEX(BASE!J:J,MATCH($A29,BASE!$A:$A,0))} -> 45909
A30: 26 | B30: 46073 | C30: Buzón | D30: {=INDEX(BASE!$C:$C,MATCH($A30,BASE!$A:$A,0))} -> ALTAMIRA | E30: {=INDEX(BASE!E:E,MATCH($A30,BASE!$A:$A,0))} -> 57064 | F30: {=INDEX(BASE!F:F,MATCH($A30,BASE!$A:$A,0))} -> MARIA CONCEPCION LOREDO AVALOS | G30: {=INDEX(BASE!J:J,MATCH($A30,BASE!$A:$A,0))} -> 45981
A31: 27 | B31: 46073 | C31: Buzón | D31: {=INDEX(BASE!$C:$C,MATCH($A31,BASE!$A:$A,0))} -> ALTAMIRA | E31: {=INDEX(BASE!E:E,MATCH($A31,BASE!$A:$A,0))} -> 57306 | F31: {=INDEX(BASE!F:F,MATCH($A31,BASE!$A:$A,0))} -> BERENICE SEGURA DEL ANGEL | G31: {=INDEX(BASE!J:J,MATCH($A31,BASE!$A:$A,0))} -> 46022
A32: 28 | B32: 46073 | C32: Buzón | D32: {=INDEX(BASE!$C:$C,MATCH($A32,BASE!$A:$A,0))} -> ALTAMIRA | E32: {=INDEX(BASE!E:E,MATCH($A32,BASE!$A:$A,0))} -> 57403 | F32: {=INDEX(BASE!F:F,MATCH($A32,BASE!$A:$A,0))} -> JOSE LUIS GUZMAN MADRIGALES | G32: {=INDEX(BASE!J:J,MATCH($A32,BASE!$A:$A,0))} -> 46021
A33: 29 | B33: 46073 | C33: Buzón | D33: {=INDEX(BASE!$C:$C,MATCH($A33,BASE!$A:$A,0))} -> ALTAMIRA | E33: {=INDEX(BASE!E:E,MATCH($A33,BASE!$A:$A,0))} -> 57363 | F33: {=INDEX(BASE!F:F,MATCH($A33,BASE!$A:$A,0))} -> GUADALUPE FLORES GUZMAN | G33: {=INDEX(BASE!J:J,MATCH($A33,BASE!$A:$A,0))} -> 45938
A34: 30 | B34: 46073 | C34: No contestó | D34: {=INDEX(BASE!$C:$C,MATCH($A34,BASE!$A:$A,0))} -> ALTAMIRA | E34: {=INDEX(BASE!E:E,MATCH($A34,BASE!$A:$A,0))} -> 104106 | F34: {=INDEX(BASE!F:F,MATCH($A34,BASE!$A:$A,0))} -> GERONIMO FRANCO DORA ALICIA | G34: {=INDEX(BASE!J:J,MATCH($A34,BASE!$A:$A,0))} -> 46058
A35: 31 | B35: 46073 | C35: No contestó | D35: {=INDEX(BASE!$C:$C,MATCH($A35,BASE!$A:$A,0))} -> ALTAMIRA | E35: {=INDEX(BASE!E:E,MATCH($A35,BASE!$A:$A,0))} -> 57088 | F35: {=INDEX(BASE!F:F,MATCH($A35,BASE!$A:$A,0))} -> MARIA VICTORIA GARCIA SOLIS | G35: {=INDEX(BASE!J:J,MATCH($A35,BASE!$A:$A,0))} -> 45967
A36: 32 | B36: 46073 | C36: Llamada efectiva (contestó) | D36: {=INDEX(BASE!$C:$C,MATCH($A36,BASE!$A:$A,0))} -> ALTAMIRA | E36: {=INDEX(BASE!E:E,MATCH($A36,BASE!$A:$A,0))} -> 57290 | F36: {=INDEX(BASE!F:F,MATCH($A36,BASE!$A:$A,0))} -> NORMA ELIZABETH SALAS MAR | G36: {=INDEX(BASE!J:J,MATCH($A36,BASE!$A:$A,0))} -> 46059 | H36: Ya tiene una lista de clientes fieles y no se quiere arriesgar a que no le paguen | I36: 5 | K36: que no se ha sentido presionada | L36: SI | M36: tiene mas comodidades | N36: perder el miedo a que no le paguen | O36: 1
A37: 33 | B37: 46073 | C37: Llamada efectiva (contestó) | D37: {=INDEX(BASE!$C:$C,MATCH($A37,BASE!$A:$A,0))} -> ALTAMIRA | E37: {=INDEX(BASE!E:E,MATCH($A37,BASE!$A:$A,0))} -> 57243 | F37: {=INDEX(BASE!F:F,MATCH($A37,BASE!$A:$A,0))} -> CLARABELLA HERNANDEZ ALONSO | G37: {=INDEX(BASE!J:J,MATCH($A37,BASE!$A:$A,0))} -> 45980 | H37: le da prioridad a los clientes cumplidos | I37: 5 | K37: se le ha dado el apoyo | L37: SI | M37: Las facilidades | N37: buscar clientes responsables | O37: 1
A38: 34 | B38: 46073 | C38: No contestó | D38: {=INDEX(BASE!$C:$C,MATCH($A38,BASE!$A:$A,0))} -> ALTAMIRA | E38: {=INDEX(BASE!E:E,MATCH($A38,BASE!$A:$A,0))} -> 57212 | F38: {=INDEX(BASE!F:F,MATCH($A38,BASE!$A:$A,0))} -> EDUVIGES RODRIGUEZ PONCE | G38: {=INDEX(BASE!J:J,MATCH($A38,BASE!$A:$A,0))} -> 46021
A39: 35 | B39: 46073 | C39: No contestó | D39: {=INDEX(BASE!$C:$C,MATCH($A39,BASE!$A:$A,0))} -> ALTAMIRA | E39: {=INDEX(BASE!E:E,MATCH($A39,BASE!$A:$A,0))} -> 106746 | F39: {=INDEX(BASE!F:F,MATCH($A39,BASE!$A:$A,0))} -> YAÑEZ MARTINEZ , MARIA LOURDES | G39: {=INDEX(BASE!J:J,MATCH($A39,BASE!$A:$A,0))} -> 45925
A40: 36 | B40: 46073 | C40: Buzón | D40: {=INDEX(BASE!$C:$C,MATCH($A40,BASE!$A:$A,0))} -> ALTAMIRA | E40: {=INDEX(BASE!E:E,MATCH($A40,BASE!$A:$A,0))} -> 110263 | F40: {=INDEX(BASE!F:F,MATCH($A40,BASE!$A:$A,0))} -> CAMPOZANO FLORES , ELENA | G40: {=INDEX(BASE!J:J,MATCH($A40,BASE!$A:$A,0))} -> 46058
...

Sheet Hoja1

Sheet BASE
A1: renglon | B1: region | C1: id_sucursal | D1: id_coordinador | E1: id_cliente | F1: Nombre | G1: Estatus | H1: TIPO | I1: fecha_alta | J1: fhUltimoCanje | K1: tipo.antiguedad | L1: %disponible | M1: tipo_colocado | N1: telefono | O1: telefono2
A2: 1 | B2: SUR | C2: ACAYUCAN | D2: 243 | E2: 86079 | F2: MARIA DE LOS ANGELES MEZA REYES | G2: ACTIVO | H2: DIAMANTE | I2: 44975 | J2: 46052 | K2: mas de 2.5 | L2: 72.463489 | M2: 46 a 60 dias | N2: 9241052982
A3: 2 | B3: SUR | C3: ACAYUCAN | D3: 1112 | E3: 86166 | F3: GABRIELA SANCHEZ GONZALEZ | G3: ACTIVO | H3: PLATA | I3: 45042 | J3: 46051 | K3: mas de 2.5 | L3: 97.000361 | M3: 106 a 120 dias | N3: 9241275593
A4: 3 | B4: SUR | C4: ACAYUCAN | D4: 243 | E4: 86052 | F4: MARIA DEL CARMEN CRUZ JIMENEZ | G4: ACTIVO | H4: ORO | I4: 44978 | J4: 46014 | K4: mas de 2.5 | L4: 74.160812 | M4: 46 a 60 dias | N4: 9241057172
A5: 4 | B5: SUR | C5: ACAYUCAN | D5: 1112 | E5: 109938 | F5: PEREZ HERNANDEZ , PETRONILA | G5: ACTIVO | H5: PLATA | I5: 45700 | J5: 46050 | K5: 6 A 1año | L5: 95.000971 | M5: 121 dias en adel | N5: 9241495415 | O5: 9241495415
A6: 5 | B6: SUR | C6: ACAYUCAN | D6: 1112 | E6: 86237 | F6: HERLINDA LOPEZ NO | G6: ACTIVO | H6: ORO | I6: 45187 | J6: 46054 | K6: 2 a 2.5años | L6: 60.324086 | M6: 30 a 45 dias | N6: 9241101679
A7: 6 | B7: SUR | C7: ACAYUCAN | D7: 1112 | E7: 116240 | F7: NOLASCO BLANCO , ERICK NAHIM | G7: ACTIVO | H7: PLATA | I7: 45990 | J7: 46050 | K7: 1 A 3MESES | L7: 93.001517 | M7: 30 a 45 dias | N7: 9241950524 | O7: 0
A8: 7 | B8: SUR | C8: ACAYUCAN | D8: 1112 | E8: 116013 | F8: HERNANDEZ MODESTO , ANA BEATRIZ | G8: ACTIVO | H8: PLATA | I8: 45981 | J8: 46028 | K8: 1 A 3MESES | L8: 91.750834 | M8: 30 a 45 dias | N8: 9731752583 | O8: 0
A9: 8 | B9: SUR | C9: ACAYUCAN | D9: 243 | E9: 86024 | F9: MARTHA REINA REYES GABINO | G9: ACTIVO | H9: ORO | I9: 44974 | J9: 45994 | K9: mas de 2.5 | L9: 69.051365 | M9: 61 a 75 dias | N9: 9241171656
A10: 9 | B10: SUR | C10: ACAYUCAN | D10: 243 | E10: 86065 | F10: NATALI DE MONSERRAT RUIZ VERGARA | G10: ACTIVO | H10: ORO | I10: 44978 | J10: 45994 | K10: mas de 2.5 | L10: 70.001736 | M10: 61 a 75 dias | N10: 9241050221
A11: 10 | B11: SUR | C11: ACAYUCAN | D11: 243 | E11: 86072 | F11: ELIZABETH GUILLEN FERNANDEZ | G11: ACTIVO | H11: PLATA | I11: 44980 | J11: 45962 | K11: mas de 2.5 | L11: 80.001132 | M11: 91 a 105 dias | N11: 9241070848
A12: 11 | B12: SUR | C12: ACAYUCAN | D12: 243 | E12: 86035 | F12: MARIA CRISTINA MUÑOZ CARDENAS | G12: ACTIVO | H12: ORO | I12: 45009 | J12: 46054 | K12: mas de 2.5 | L12: 61.329538 | M12: 61 a 75 dias | N12: 9241087001
A13: 12 | B13: SUR | C13: ACAYUCAN | D13: 1112 | E13: 109931 | F13: AGUIRRE ENRIQUEZ , GUADALUPE | G13: ACTIVO | H13: PLATA | I13: 45698 | J13: 46024 | K13: 6 A 1año | L13: 75.10129 | M13: 30 a 45 dias | N13: 9241349894 | O13: 9241349894
A14: 13 | B14: SUR | C14: ACAYUCAN | D14: 1112 | E14: 103239 | F14: TADEO ANTONIO EVA | G14: ACTIVO | H14: PLATA | I14: 45281 | J14: 46054 | K14: 2 a 2.5años | L14: 83.572242 | M14: 46 a 60 dias | N14: 9221592600 | O14: 0
A15: 14 | B15: SUR | C15: ACAYUCAN | D15: 243 | E15: 86105 | F15: ANGELICA TREJO PEREZ | G15: ACTIVO | H15: ORO | I15: 44974 | J15: 46045 | K15: mas de 2.5 | L15: 47.373964 | M15: 15 a 29 dias | N15: 9241387844
A16: 15 | B16: SUR | C16: ACAYUCAN | D16: 1112 | E16: 86149 | F16: PETRA RAMIREZ USCANGA | G16: ACTIVO | H16: ORO | I16: 45007 | J16: 46056 | K16: mas de 2.5 | L16: 56.107532 | M16: 30 a 45 dias | N16: 9241526974
A17: 16 | B17: SUR | C17: ACAYUCAN | D17: 243 | E17: 86041 | F17: ZORAIDA MENDOZA DE JESUS | G17: ACTIVO | H17: PLATA | I17: 44974 | J17: 46056 | K17: mas de 2.5 | L17: 81.444511 | M17: 91 a 105 dias | N17: 9241466507
A18: 17 | B18: SUR | C18: ACAYUCAN | D18: 243 | E18: 86053 | F18: NICOLASA HERNANDEZ MARTINEZ | G18: ACTIVO | H18: PLATA | I18: 44978 | J18: 45980 | K18: mas de 2.5 | L18: 90.000714 | M18: 76 a 90 dias | N18: 9241331245
A19: 18 | B19: SUR | C19: ACAYUCAN | D19: 243 | E19: 86037 | F19: ANA LUISA ZENTENO MARTINEZ | G19: ACTIVO | H19: PLATA | I19: 44979 | J19: 46003 | K19: mas de 2.5 | L19: 62.560448 | M19: 46 a 60 dias | N19: 9241058513
A20: 19 | B20: SUR | C20: ACAYUCAN | D20: 243 | E20: 116138 | F20: GUILLEN SANTIAGO , ALONDRA | G20: ACTIVO | H20: PLATA | I20: 45986 | J20: 45997 | K20: 1 A 3MESES | L20: 87.501349 | M20: 61 a 75 dias | N20: 9241492568 | O20: 0
A21: 20 | B21: SUR | C21: ACAYUCAN | D21: 243 | E21: 86083 | F21: DORA PEREZ GOMEZ | G21: ACTIVO | H21: PLATA | I21: 44974 | J21: 46017 | K21: mas de 2.5 | L21: 52.502849 | M21: 30 a 45 dias | N21: 9241272818
A22: 21 | B22: SUR | C22: ACAYUCAN | D22: 243 | E22: 103924 | F22: CORDERO RAMIREZ MARIBEL | G22: ACTIVO | H22: PLATA | I22: 45332 | J22: 45965 | K22: 1.5 a 2años | L22: 90.00092 | M22: 91 a 105 dias | N22: 9242102229 | O22: 0
A23: 22 | B23: SUR | C23: ACAYUCAN | D23: 243 | E23: 107170 | F23: ISIDORO CANDIDO , ALEJANDRA | G23: ACTIVO | H23: PLATA | I23: 45516 | J23: 45962 | K23: 1 a 1.5años | L23: 94.444956 | M23: 91 a 105 dias | N23: 9241172455 | O23: 9241172455
A24: 23 | B24: SUR | C24: ACAYUCAN | D24: 243 | E24: 110417 | F24: PULIDO LICONA , VERONICA | G24: ACTIVO | H24: PLATA | I24: 45734 | J24: 46003 | K24: 6 A 1año | L24: 68.57574 | M24: 46 a 60 dias | N24: 9242101661 | O24: 9242101661
A25: 24 | B25: SUR | C25: ACAYUCAN | D25: 1112 | E25: 108567 | F25: DOMINGUEZ ALFONSO , MARIA ELENA | G25: ACTIVO | H25: PLATA | I25: 45593 | J25: 46054 | K25: 1 a 1.5años | L25: 46.673452 | M25: 46 a 60 dias | N25: 9241293751 | O25: 0
A26: 25 | B26: NORESTE | C26: ALTAMIRA | D26: 1149 | E26: 57216 | F26: MARIA GUADALUPE AQUINO BANDA | G26: ACTIVO | H26: DIAMANTE | I26: 44432 | J26: 45909 | K26: mas de 2.5 | L26: 98.561209 | M26: 121 dias en adel | N26: 8331821626
A27: 26 | B27: NORESTE | C27: ALTAMIRA | D27: 1149 | E27: 57064 | F27: MARIA CONCEPCION LOREDO AVALOS | G27: ACTIVO | H27: DIAMANTE VIP | I27: 44126 | J27: 45981 | K27: mas de 2.5 | L27: 68.518903 | M27: 76 a 90 dias | N27: 8331287549
A28: 27 | B28: NORESTE | C28: ALTAMIRA | D28: 1149 | E28: 57306 | F28: BERENICE SEGURA DEL ANGEL | G28: ACTIVO | H28: DIAMANTE VIP | I28: 44691 | J28: 46022 | K28: mas de 2.5 | L28: 58.129837 | M28: 30 a 45 dias | N28: 8332065948
A29: 28 | B29: NORESTE | C29: ALTAMIRA | D29: 160 | E29: 57403 | F29: JOSE LUIS GUZMAN MADRIGALES | G29: ACTIVO | H29: DIAMANTE | I29: 44946 | J29: 46021 | K29: mas de 2.5 | L29: 64.809509 | M29: 30 a 45 dias | N29: 8333674373
A30: 29 | B30: NORESTE | C30: ALTAMIRA | D30: 1149 | E30: 57363 | F30: GUADALUPE FLORES GUZMAN | G30: ACTIVO | H30: PLATINO | I30: 44837 | J30: 45938 | K30: mas de 2.5 | L30: 96.840713 | M30: 121 dias en adel | N30: 8334261212
A31: 30 | B31: NORESTE | C31: ALTAMIRA | D31: 1285 | E31: 104106 | F31: GERONIMO FRANCO DORA ALICIA | G31: ACTIVO | H31: DIAMANTE | I31: 45345 | J31: 46058 | K31: 1.5 a 2años | L31: 55.571439 | M31: 46 a 60 dias | N31: 8331060482 | O31: 0
A32: 31 | B32: NORESTE | C32: ALTAMIRA | D32: 1149 | E32: 57088 | F32: MARIA VICTORIA GARCIA SOLIS | G32: ACTIVO | H32: ORO | I32: 44144 | J32: 45967 | K32: mas de 2.5 | L32: 93.667007 | M32: 91 a 105 dias | N32: 8334364867
A33: 32 | B33: NORESTE | C33: ALTAMIRA | D33: 160 | E33: 57290 | F33: NORMA ELIZABETH SALAS MAR | G33: ACTIVO | H33: PLATINO | I33: 44673 | J33: 46059 | K33: mas de 2.5 | L33: 55.541202 | M33: 15 a 29 dias | N33: 8333391534
A34: 33 | B34: NORESTE | C34: ALTAMIRA | D34: 160 | E34: 57243 | F34: CLARABELLA HERNANDEZ ALONSO | G34: ACTIVO | H34: ORO | I34: 44604 | J34: 45980 | K34: mas de 2.5 | L34: 84.070146 | M34: 76 a 90 dias | N34: 8333223438
A35: 34 | B35: NORESTE | C35: ALTAMIRA | D35: 160 | E35: 57212 | F35: EDUVIGES RODRIGUEZ PONCE | G35: ACTIVO | H35: PLATINO | I35: 44620 | J35: 46021 | K35: mas de 2.5 | L35: 54.845562 | M35: 30 a 45 dias | N35: 8332040294
A36: 35 | B36: NORESTE | C36: ALTAMIRA | D36: 160 | E36: 106746 | F36: YAÑEZ MARTINEZ , MARIA LOURDES | G36: ACTIVO | H36: PLATA | I36: 45488 | J36: 45925 | K36: 1.5 a 2años | L36: 91.667234 | M36: 121 dias en adel | N36: 8334121349 | O36: 0
A37: 36 | B37: NORESTE | C37: ALTAMIRA | D37: 1285 | E37: 110263 | F37: CAMPOZANO FLORES , ELENA | G37: ACTIVO | H37: ORO | I37: 45723 | J37: 46058 | K37: 6 A 1año | L37: 64.858864 | M37: 30 a 45 dias | N37: 8334279329 | O37: 0
A38: 37 | B38: NORESTE | C38: ALTAMIRA | D38: 160 | E38: 57299 | F38: VICTORIA LARA ZARAGOZA | G38: ACTIVO | H38: PLATINO | I38: 44728 | J38: 46053 | K38: mas de 2.5 | L38: 48.540516 | M38: 30 a 45 dias | N38: 8332844530
A39: 38 | B39: NORESTE | C39: ALTAMIRA | D39: 160 | E39: 113504 | F39: SOBREVILLA PEREZ , AURORA | G39: ACTIVO | H39: ORO | I39: 45887 | J39: 46007 | K39: 3 A 6MESES | L39: 61.43262 | M39: 46 a 60 dias | N39: 8333419217 | O39: 0
A40: 39 | B40: NORESTE | C40: ALTAMIRA | D40: 1149 | E40: 57345 | F40: ANA MARISELA SILVA HERNANDEZ | G40: ACTIVO | H40: ORO | I40: 44782 | J40: 46024 | K40: mas de 2.5 | L40: 52.446893 | M40: 30 a 45 dias | N40: 8332396089
...

Sheet Hoja2
A1: id_cliente | B1: nombre | C1: Estatus | D1: TIPO | E1: limite | F1: DISPONIBLE | G1: SALDO | H1: Bolsa | I1: Disponible_Bolsa | J1: telefono | K1: telefono2
A2: 103239 | B2: TADEO ANTONIO EVA | C2: ACTIVO | D2: PLATA | E2: 8000 | F2: 625.3709 | G2: 13992.645 | H2: 1446 | I2: 0 | J2: 9221592600
A3: 103924 | B3: CORDERO RAMIREZ MARIBEL | C3: ACTIVO | D3: PLATA | E3: 12000 | F3: 11000.476 | G3: 1639.37 | H3: 1855 | I3: 0 | J3: 9242102229
A4: 107170 | B4: ISIDORO CANDIDO , ALEJANDRA | C4: ACTIVO | D4: PLATA | E4: 18000 | F4: 17400.104 | G4: 983.92 | H4: 1905 | I4: 0 | J4: 9241172455 | K4: 9241172455
A5: 107587 | B5: RODRIGUEZ PEREZ , BERENICE | C5: ACTIVO | D5: PLATA | E5: 43000 | F5: 8049.4267 | G5: 55200.43 | H5: 2177 | I5: 0 | J5: 2941551322 | K5: 2941551322
A6: 108567 | B6: DOMINGUEZ ALFONSO , MARIA ELENA | C6: ACTIVO | D6: PLATA | E6: 30000 | F6: 8177.492 | G6: 35967.25 | H6: 1968 | I6: 0 | J6: 9241293751
A7: 109931 | B7: AGUIRRE ENRIQUEZ , GUADALUPE | C7: ACTIVO | D7: PLATA | E7: 50000 | F7: 41286.141 | G7: 13419 | H7: 1351 | I7: 0 | J7: 9241349894 | K7: 9241349894
A8: 109938 | B8: PEREZ HERNANDEZ , PETRONILA | C8: ACTIVO | D8: PLATA | E8: 50000 | F8: 43034.308 | G8: 10863.42 | H8: 876 | I8: 0 | J8: 9241495415 | K8: 9241495415
A9: 110417 | B9: PULIDO LICONA , VERONICA | C9: ACTIVO | D9: PLATA | E9: 13000 | F9: 8200.8437 | G9: 7415.26 | H9: 1954 | I9: 0 | J9: 9242101661 | K9: 9242101661
A10: 116013 | B10: HERNANDEZ MODESTO , ANA BEATRIZ | C10: ACTIVO | D10: PLATA | E10: 50000 | F10: 47125.29 | G10: 4371 | H10: 955 | I10: 0 | J10: 9731752583
A11: 116138 | B11: GUILLEN SANTIAGO , ALONDRA | C11: ACTIVO | D11: PLATA | E11: 10000 | F11: 7750.7786 | G11: 3428.1 | H11: 1704 | I11: 0 | J11: 9241492568
A12: 116240 | B12: NOLASCO BLANCO , ERICK NAHIM | C12: ACTIVO | D12: PLATA | E12: 50000 | F12: 30476.985 | G12: 29980.33 | H12: 931 | I12: 0 | J12: 9241950524
A13: 86024 | B13: MARTHA REINA REYES GABINO | C13: ACTIVO | D13: ORO | E13: 63000 | F13: 50701.215 | G13: 19117 | H13: 1093 | I13: 0 | J13: (924) 117-1656 | K13: ( ) -
A14: 86035 | B14: MARIA CRISTINA MUÑOZ CARDENAS | C14: ACTIVO | D14: ORO | E14: 64600 | F14: 38752.198 | G14: 42408.09 | H14: 1256 | I14: 0 | J14: (924) 108-7001 | K14: ( ) -
A15: 86037 | B15: ANA LUISA ZENTENO MARTINEZ | C15: ACTIVO | D15: PLATA | E15: 43000 | F15: 32134.215 | G15: 17322.51 | H15: 1687 | I15: 0 | J15: (924) 105-8513 | K15: ( ) -
A16: 86041 | B16: ZORAIDA MENDOZA DE JESUS | C16: ACTIVO | D16: PLATA | E16: 35000 | F16: 25251.342 | G16: 15170.34 | H16: 1641 | I16: 0 | J16: (924) 146-6507 | K16: ( ) -
A17: 86052 | B17: MARIA DEL CARMEN CRUZ JIMENEZ | C17: ACTIVO | D17: ORO | E17: 65000 | F17: 54004.557 | G17: 17246.28 | H17: 833 | I17: 0 | J17: (924) 105-7172 | K17: ( ) -
A18: 86053 | B18: NICOLASA HERNANDEZ MARTINEZ | C18: ACTIVO | D18: PLATA | E18: 30000 | F18: 28400.554 | G18: 2519.21 | H18: 1684 | I18: 0 | J18: (924) 133-1245 | K18: ( ) -
A19: 86065 | B19: NATALI DE MONSERRAT RUIZ VERGARA | C19: ACTIVO | D19: ORO | E19: 60000 | F19: 45429.276 | G19: 26009.86 | H19: 1153 | I19: 0 | J19: (924) 105-0221 | K19: ( ) -
A20: 86071 | B20: SILVIA GUADALUPE GONZALEZ MORTERA | C20: ACTIVO | D20: PLATA | E20: 53000 | F20: 44652.847 | G20: 31701.465 | H20: #N/A | I20: 0 | J20: (924) 114-6171 | K20: ( ) -
A21: 86072 | B21: ELIZABETH GUILLEN FERNANDEZ | C21: ACTIVO | D21: PLATA | E21: 50000 | F21: 46000.634 | G21: 6239.26 | H21: 1238 | I21: 0 | J21: (924) 107-0848 | K21: ( ) -
A22: 86079 | B22: MARIA DE LOS ANGELES MEZA REYES | C22: ACTIVO | D22: DIAMANTE | E22: 126001 | F22: 87908.6 | G22: 59338.13 | H22: 169 | I22: 0 | J22: (924) 105-2982 | K22: ( ) -
A23: 86083 | B23: DORA PEREZ GOMEZ | C23: ACTIVO | D23: PLATA | E23: 42000 | F23: 29051.052 | G23: 23351.87 | H23: 1812 | I23: 0 | J23: (924) 127-2818 | K23: ( ) -
A24: 86105 | B24: ANGELICA TREJO PEREZ | C24: ACTIVO | D24: ORO | E24: 64697 | F24: 39598.995 | G24: 39019.28 | H24: 1579 | I24: 0 | J24: (924) 138-7844 | K24: ( ) -
A25: 86149 | B25: PETRA RAMIREZ USCANGA | C25: ACTIVO | D25: ORO | E25: 52000 | F25: 30068.168 | G25: 36942.28 | H25: 1627 | I25: 0 | J25: (924) 152-6974 | K25: ( ) -
A26: 86166 | B26: GABRIELA SANCHEZ GONZALEZ | C26: ACTIVO | D26: PLATA | E26: 60000 | F26: 52572.433 | G26: 13129.87 | H26: 491 | I26: 0 | J26: (924) 127-5593 | K26: ( ) -
A27: 86237 | B27: HERLINDA LOPEZ NO | C27: ACTIVO | D27: ORO | E27: 78600 | F27: 54502.105 | G27: 45312 | H27: 886 | I27: 0 | J27: (924) 110-1679 | K27: ( ) -
A28: 104106 | B28: GERONIMO FRANCO DORA ALICIA | C28: ACTIVO | D28: DIAMANTE | E28: 147000 | F28: 76674.95 | G28: 143505.64 | H28: 237 | I28: 0 | J28: 8331060482
A29: 106746 | B29: YAÑEZ MARTINEZ , MARIA LOURDES | C29: ACTIVO | D29: PLATA | E29: 50000 | F29: 47500.17 | G29: 4134 | H29: 959 | I29: 0 | J29: 8334121349
A30: 107732 | B30: VIGIL IBARRA , EUNICE | C30: ACTIVO | D30: PLATINO | E30: 113000 | F30: 26714.454 | G30: 167821.6 | H30: 1931 | I30: 0 | J30: 8335143760
A31: 108264 | B31: DE LA ROSA SANCHEZ , MA ESTHER | C31: ACTIVO | D31: PLATA | E31: 30000 | F31: 18700.787 | G31: 25943.25 | H31: 2056 | I31: 0 | J31: 8333771045
A32: 110263 | B32: CAMPOZANO FLORES , ELENA | C32: ACTIVO | D32: ORO | E32: 70000 | F32: 43915.903 | G32: 43906 | H32: 986 | I32: 0 | J32: 8334279329
A33: 113504 | B33: SOBREVILLA PEREZ , AURORA | C33: ACTIVO | D33: ORO | E33: 70000 | F33: 54201.638 | G33: 23440 | H33: 1113 | I33: 0 | J33: 8333419217
A34: 115703 | B34: ANDONEY SANTIAGO , TERESA | C34: ACTIVO | D34: PLATA | E34: 50000 | F34: 41001.123 | G34: 16440 | H34: 1326 | I34: 0 | J34: 8333408365
A35: 57064 | B35: MARIA CONCEPCION LOREDO AVALOS | C35: ACTIVO | D35: DIAMANTE VIP | E35: 155000 | F35: 125202.85 | G35: 72384.33 | H35: 95 | I35: 0 | J35: (833) 128-7549 | K35: ( ) -
A36: 57088 | B36: MARIA VICTORIA GARCIA SOLIS | C36: ACTIVO | D36: ORO | E36: 75000 | F36: 72750.803 | G36: 3511.89 | H36: 346 | I36: 0 | J36: (833) 436-4867 | K36: ( ) -
A37: 57163 | B37: VILLALOBOS ARIAS , AMANDA | C37: ACTIVO | D37: PLATA | E37: 50000 | F37: 27752.382 | G37: 44550 | H37: 1488 | I37: 0 | J37: 8333881621
A38: 57212 | B38: EDUVIGES RODRIGUEZ PONCE | C38: ACTIVO | D38: PLATINO | E38: 95000 | F38: 65702.345 | G38: 48707 | H38: 637 | I38: 0 | J38: (833) 204-0294 | K38: ( ) -
A39: 57216 | B39: MARIA GUADALUPE AQUINO BANDA | C39: ACTIVO | D39: DIAMANTE | E39: 139000 | F39: 138000.04 | G39: 2065 | H39: 31 | I39: 0 | J39: (833) 182-1626 | K39: ( ) -
A40: 57225 | B40: MARTHA PATRICIA LOZANO RIVAS | C40: ACTIVO | D40: PLATA | E40: 50000 | F40: 41394.411 | G40: 15461.02 | H40: 1337 | I40: 0 | J40: (833) 534-6271 | K40: (833) 362-6234
...

Sheet Hoja4
A1: Llamada efectiva (contestó) | C1: 1 | E1: NO
A2: No contestó | C2: 2 | E2: SI
A3: Buzón | C3: 3
A4: Número incorrecto | C4: 4
A5: Teléfono fuera de servicio | C5: 5
A6: Reagendar llamada
A7: Se negó a contestar
A8: Número cambiado
A9: Otro
